Workbook

Sheet Transaction Log
A1: KFC HEDGE FUND // TRANSACTION LEDGER
A2: Cash flows in and out. Fund Balance auto-updates every row.
A3: Blue = input | White = formula | Green = cross-sheet
A4: # | B4: Date | C4: Player Name | D4: Type | E4: Deposit (+) | F4: Withdrawal (−) | G4: Net Flow | H4: Fund Balance After | I4: Note / Reference | J4: Verified?
A5: =IFERROR(ROW()-4,"") -> 1 | B5: 46082 | C5: Kimmo | D5: Deposit | E5: 2000000000 | G5: =IF(AND(E5="",F5=""),"",IFERROR(E5,0)-IFERROR(F5,0)) -> 2000000000 | H5: =IF(AND(E5="",F5=""),"",G5) -> 2000000000 | I5: Fund manager initial funding | J5: Yes
A6: =IFERROR(ROW()-4,"") -> 2 | B6: 46093 | C6: Andre | D6: Deposit | E6: 50000000 | G6: =IF(AND(E6="",F6=""),"",IFERROR(E6,0)-IFERROR(F6,0)) -> 50000000 | H6: =IF(AND(E6="",F6=""),"",H5+G6) -> 2050000000 | I6: First player deposit | J6: Yes
A7: =IFERROR(ROW()-4,"") -> 3 | G7: =IF(AND(E7="",F7=""),"",IFERROR(E7,0)-IFERROR(F7,0)) | H7: =IF(AND(E7="",F7=""),"",H6+G7)
A8: =IFERROR(ROW()-4,"") -> 4 | G8: =IF(AND(E8="",F8=""),"",IFERROR(E8,0)-IFERROR(F8,0)) | H8: =IF(AND(E8="",F8=""),"",H7+G8)
A9: =IFERROR(ROW()-4,"") -> 5 | G9: =IF(AND(E9="",F9=""),"",IFERROR(E9,0)-IFERROR(F9,0)) | H9: =IF(AND(E9="",F9=""),"",H8+G9)
A10: =IFERROR(ROW()-4,"") -> 6 | G10: =IF(AND(E10="",F10=""),"",IFERROR(E10,0)-IFERROR(F10,0)) | H10: =IF(AND(E10="",F10=""),"",H9+G10)
A11: =IFERROR(ROW()-4,"") -> 7 | G11: =IF(AND(E11="",F11=""),"",IFERROR(E11,0)-IFERROR(F11,0)) | H11: =IF(AND(E11="",F11=""),"",H10+G11)
A12: =IFERROR(ROW()-4,"") -> 8 | G12: =IF(AND(E12="",F12=""),"",IFERROR(E12,0)-IFERROR(F12,0)) | H12: =IF(AND(E12="",F12=""),"",H11+G12)
A13: =IFERROR(ROW()-4,"") -> 9 | G13: =IF(AND(E13="",F13=""),"",IFERROR(E13,0)-IFERROR(F13,0)) | H13: =IF(AND(E13="",F13=""),"",H12+G13)
A14: =IFERROR(ROW()-4,"") -> 10 | G14: =IF(AND(E14="",F14=""),"",IFERROR(E14,0)-IFERROR(F14,0)) | H14: =IF(AND(E14="",F14=""),"",H13+G14)
A15: =IFERROR(ROW()-4,"") -> 11 | G15: =IF(AND(E15="",F15=""),"",IFERROR(E15,0)-IFERROR(F15,0)) | H15: =IF(AND(E15="",F15=""),"",H14+G15)
A16: =IFERROR(ROW()-4,"") -> 12 | G16: =IF(AND(E16="",F16=""),"",IFERROR(E16,0)-IFERROR(F16,0)) | H16: =IF(AND(E16="",F16=""),"",H15+G16)
A17: =IFERROR(ROW()-4,"") -> 13 | G17: =IF(AND(E17="",F17=""),"",IFERROR(E17,0)-IFERROR(F17,0)) | H17: =IF(AND(E17="",F17=""),"",H16+G17)
A18: =IFERROR(ROW()-4,"") -> 14 | G18: =IF(AND(E18="",F18=""),"",IFERROR(E18,0)-IFERROR(F18,0)) | H18: =IF(AND(E18="",F18=""),"",H17+G18)
... A106: =IFERROR(ROW()-4,"") -> 102 | G106: =IF(AND(E106="",F106=""),"",IFERROR(E106,0)-IFERROR(F106,0)) | H106: =IF(AND(E106="",F106=""),"",H105+G106)

Sheet Positions
A1: POSITIONS // TRADE TRACKER
A2: Open=live P&L | Closed=locked P&L | Blue=input | White=formula | Green=cross-sheet
A3: Col O=Exit/Cur Price | Col V=Stop Loss | Col W=Take Profit | Col AF=SL/TP Status | Col AH=Liquidation Price
A5: # | B5: Status | C5: Asset Class | D5: Ticker/Name | E5: Long/Short | F5: Entry Date | G5: Entry Price | H5: Qty | I5: Leverage (x) | J5: Margin % (1/Lev) | K5: Notional Exp ($) | L5: Margin Req ($) | M5: Warning Threshold % | N5: Margin Status | O5: Exit/Cur Price | P5: Mkt/Exit Val ($) | Q5: P&L ($) | R5: P&L (%) | S5: % of Fund | T5: Exit Date | U5: Hold (days) | V5: Stop Loss | W5: Take Profit | X5: SL Distance ($) | Y5: SL Distance (%) | Z5: TP Distance ($) | AA5: TP Distance (%) | AB5: Notes | AC5: Max Loss vs SL | AD5: Locked Exit Price | AE5: Drawdown from Entry % | AF5: SL/TP Triggered? | AG5: Auto Exit Price | AH5: Liquidation Price
A6: =IFERROR(ROW()-5,"") -> 1 | B6: Closed | C6: Stock | D6: NVDA | E6: Long | F6: 46091 | G6: 307.98 | H6: 2500000 | I6: 20 | J6: =IFERROR(1/I6,"") -> 0.05 | K6: =IFERROR(G6*H6*I6,"") -> 15399000000 | L6: =IFERROR(G6*H6,"") -> 769950000 | M6: 0.5 | N6: =IFERROR(IF(B6<>"Open","—",IF((G6*H6+Q6)<=0,"LIQUIDATION",IF((G6*H6+Q6)/(G6*H6)<=M6,"WARNING","OK"))),"—") -> — | O6: 305.56 | P6: =IFERROR((IF(AND(B6="Closed",AD6<>""),AD6,O6))*H6,"") -> 763900000 | Q6: =IFERROR(IF(E6="Long",(IF(AND(B6="Closed",AD6<>""),AD6,O6)-G6)*H6*I6,(G6-IF(AND(B6="Closed",AD6<>""),AD6,O6))*H6*I6),"") -> -1.21e+08 | R6: =IFERROR(Q6/(G6*H6),"") -> -0.15715306 | S6: =IFERROR(L6/(IFERROR(LOOKUP(2,1/('Transaction Log'!H5:H106<>""),'Transaction Log'!H5:H106),0)),"") -> 0.37558537 | T6: 46094 | U6: =IFERROR(IF(B6="Closed",T6-F6,TODAY()-F6),"") -> 3 | V6: 305.56 | W6: 312.32 | X6: =IFERROR(IF(OR(V6="",I6=""),"—",IF(E6="Long",(G6-V6)*H6*I6,(V6-G6)*H6*I6)),"—") -> 1.21e+08 | Y6: =IFERROR(IF(OR(V6="",G6=""),"—",IF(E6="Long",(G6-V6)/G6,(V6-G6)/G6)),"—") -> 0.0078576531 | Z6: =IFERROR(IF(OR(W6="",I6=""),"—",IF(E6="Long",(W6-G6)*H6*I6,(G6-W6)*H6*I6)),"—") -> 2.17e+08 | AA6: =IFERROR(IF(OR(W6="",G6=""),"—",IF(E6="Long",(W6-G6)/G6,(G6-W6)/G6)),"—") -> 0.014091824 | AC6: =IFERROR(IF(E6="Long",(G6-V6)*H6*I6,(V6-G6)*H6*I6),"") -> 1.21e+08 | AD6: =IFERROR(IF(OR(AF6="STOP LOSS HIT",AF6="TAKE PROFIT HIT"),AG6,""),"") -> 305.56 | AE6: =IFERROR(IF(E6="Long",(IF(AND(B6="Closed",AD6<>""),AD6,O6)-G6)/G6,(G6-IF(AND(B6="Closed",AD6<>""),AD6,O6))/G6),"") -> -0.0078576531 | AF6: =IFERROR(IF(OR(V6="",W6=""),"No SL/TP",IF(E6="Long",IF(O6<=V6,"STOP LOSS HIT",IF(O6>=W6,"TAKE PROFIT HIT",IF(B6="Closed","CLOSED","Active"))),IF(O6>=V6,"STOP LOSS HIT",IF(O6<=W6,"TAKE PROFIT HIT",IF(B6="Closed","CLOSED","Active"))))),"—") -> STOP LOSS HIT | AG6: =IFERROR(IF(E6="Long",IF(O6<=V6,V6,IF(O6>=W6,W6,"")),IF(O6>=V6,V6,IF(O6<=W6,W6,""))),"") -> 305.56 | AH6: =IFERROR(IF(B6<>"Open","—",IF(E6="Long",G6*(1-1/I6),G6*(1+1/I6))),"—") -> —
A7: =IFERROR(ROW()-5,"") -> 2 | B7: Closed | C7: Stock | D7: META | E7: Long | F7: 46092 | G7: 278.53 | H7: 575000 | I7: 20 | J7: =IFERROR(1/I7,"") -> 0.05 | K7: =IFERROR(G7*H7*I7,"") -> 3.203095e+09 | L7: =IFERROR(G7*H7,"") -> 1.6015475e+08 | M7: 0.5 | N7: =IFERROR(IF(B7<>"Open","—",IF((G7*H7+Q7)<=0,"LIQUIDATION",IF((G7*H7+Q7)/(G7*H7)<=M7,"WARNING","OK"))),"—") -> — | O7: 273.5 | P7: =IFERROR((IF(AND(B7="Closed",AD7<>""),AD7,O7))*H7,"") -> 157262500 | Q7: =IFERROR(IF(E7="Long",(IF(AND(B7="Closed",AD7<>""),AD7,O7)-G7)*H7*I7,(G7-IF(AND(B7="Closed",AD7<>""),AD7,O7))*H7*I7),"") -> -57845000 | R7: =IFERROR(Q7/(G7*H7),"") -> -0.36118192 | S7: =IFERROR(L7/(IFERROR(LOOKUP(2,1/('Transaction Log'!H5:H106<>""),'Transaction Log'!H5:H106),0)),"") -> 0.078124268 | T7: 46092 | U7: =IFERROR(IF(B7="Closed",T7-F7,TODAY()-F7),"") -> 0 | V7: 273.5 | W7: 294.56 | X7: =IFERROR(IF(OR(V7="",I7=""),"—",IF(E7="Long",(G7-V7)*H7*I7,(V7-G7)*H7*I7)),"—") -> 57845000 | Y7: =IFERROR(IF(OR(V7="",G7=""),"—",IF(E7="Long",(G7-V7)/G7,(V7-G7)/G7)),"—") -> 0.018059096 | Z7: =IFERROR(IF(OR(W7="",I7=""),"—",IF(E7="Long",(W7-G7)*H7*I7,(G7-W7)*H7*I7)),"—") -> 1.84345e+08 | AA7: =IFERROR(IF(OR(W7="",G7=""),"—",IF(E7="Long",(W7-G7)/G7,(G7-W7)/G7)),"—") -> 0.057552149 | AC7: =IFERROR(IF(E7="Long",(G7-V7)*H7*I7,(V7-G7)*H7*I7),"") -> 57845000 | AD7: =IFERROR(IF(OR(AF7="STOP LOSS HIT",AF7="TAKE PROFIT HIT"),AG7,""),"") -> 273.5 | AE7: =IFERROR(IF(E7="Long",(IF(AND(B7="Closed",AD7<>""),AD7,O7)-G7)/G7,(G7-IF(AND(B7="Closed",AD7<>""),AD7,O7))/G7),"") -> -0.018059096 | AF7: =IFERROR(IF(OR(V7="",W7=""),"No SL/TP",IF(E7="Long",IF(O7<=V7,"STOP LOSS HIT",IF(O7>=W7,"TAKE PROFIT HIT",IF(B7="Closed","CLOSED","Active"))),IF(O7>=V7,"STOP LOSS HIT",IF(O7<=W7,"TAKE PROFIT HIT",IF(B7="Closed","CLOSED","Active"))))),"—") -> STOP LOSS HIT | AG7: =IFERROR(IF(E7="Long",IF(O7<=V7,V7,IF(O7>=W7,W7,"")),IF(O7>=V7,V7,IF(O7<=W7,W7,""))),"") -> 273.5 | AH7: =IFERROR(IF(B7<>"Open","—",IF(E7="Long",G7*(1-1/I7),G7*(1+1/I7))),"—") -> —
A8: =IFERROR(ROW()-5,"") -> 3 | B8: Closed | C8: Forex | D8: AUD/USD | E8: Short | F8: 46090 | G8: 0.7798 | H8: 300000000 | I8: 20 | J8: =IFERROR(1/I8,"") -> 0.05 | K8: =IFERROR(G8*H8*I8,"") -> 4678800000 | L8: =IFERROR(G8*H8,"") -> 233940000 | M8: 0.5 | N8: =IFERROR(IF(B8<>"Open","—",IF((G8*H8+Q8)<=0,"LIQUIDATION",IF((G8*H8+Q8)/(G8*H8)<=M8,"WARNING","OK"))),"—") -> — | O8: 0.777 | P8: =IFERROR((IF(AND(B8="Closed",AD8<>""),AD8,O8))*H8,"") -> 233100000 | Q8: =IFERROR(IF(E8="Long",(IF(AND(B8="Closed",AD8<>""),AD8,O8)-G8)*H8*I8,(G8-IF(AND(B8="Closed",AD8<>""),AD8,O8))*H8*I8),"") -> 16800000 | R8: =IFERROR(Q8/(G8*H8),"") -> 0.071813285 | S8: =IFERROR(L8/(IFERROR(LOOKUP(2,1/('Transaction Log'!H5:H106<>""),'Transaction Log'!H5:H106),0)),"") -> 0.11411707 | T8: 46092 | U8: =IFERROR(IF(B8="Closed",T8-F8,TODAY()-F8),"") -> 2 | V8: 0.777 | W8: 0.774 | X8: =IFERROR(IF(OR(V8="",I8=""),"—",IF(E8="Long",(G8-V8)*H8*I8,(V8-G8)*H8*I8)),"—") -> -16800000 | Y8: =IFERROR(IF(OR(V8="",G8=""),"—",IF(E8="Long",(G8-V8)/G8,(V8-G8)/G8)),"—") -> -0.0035906643 | Z8: =IFERROR(IF(OR(W8="",I8=""),"—",IF(E8="Long",(W8-G8)*H8*I8,(G8-W8)*H8*I8)),"—") -> 34800000 | AA8: =IFERROR(IF(OR(W8="",G8=""),"—",IF(E8="Long",(W8-G8)/G8,(G8-W8)/G8)),"—") -> 0.0074378046 | AB8: Position volume added | AC8: =IFERROR(IF(E8="Long",(G8-V8)*H8*I8,(V8-G8)*H8*I8),"") -> -16800000 | AD8: =IFERROR(IF(OR(AF8="STOP LOSS HIT",AF8="TAKE PROFIT HIT"),AG8,""),"") -> 0.777 | AE8: =IFERROR(IF(E8="Long",(IF(AND(B8="Closed",AD8<>""),AD8,O8)-G8)/G8,(G8-IF(AND(B8="Closed",AD8<>""),AD8,O8))/G8),"") -> 0.0035906643 | AF8: =IFERROR(IF(OR(V8="",W8=""),"No SL/TP",IF(E8="Long",IF(O8<=V8,"STOP LOSS HIT",IF(O8>=W8,"TAKE PROFIT HIT",IF(B8="Closed","CLOSED","Active"))),IF(O8>=V8,"STOP LOSS HIT",IF(O8<=W8,"TAKE PROFIT HIT",IF(B8="Closed","CLOSED","Active"))))),"—") -> STOP LOSS HIT | AG8: =IFERROR(IF(E8="Long",IF(O8<=V8,V8,IF(O8>=W8,W8,"")),IF(O8>=V8,V8,IF(O8<=W8,W8,""))),"") -> 0.777 | AH8: =IFERROR(IF(B8<>"Open","—",IF(E8="Long",G8*(1-1/I8),G8*(1+1/I8))),"—") -> —
A9: =IFERROR(ROW()-5,"") -> 4 | B9: Closed | C9: Futures | D9: Gold | E9: Long | F9: 46090 | G9: 5106.38 | H9: 160000 | I9: 20 | J9: =IFERROR(1/I9,"") -> 0.05 | K9: =IFERROR(G9*H9*I9,"") -> 16340416000 | L9: =IFERROR(G9*H9,"") -> 817020800 | M9: 0.5 | N9: =IFERROR(IF(B9<>"Open","—",IF((G9*H9+Q9)<=0,"LIQUIDATION",IF((G9*H9+Q9)/(G9*H9)<=M9,"WARNING","OK"))),"—") -> — | O9: 5234 | P9: =IFERROR((IF(AND(B9="Closed",AD9<>""),AD9,O9))*H9,"") -> 837440000 | Q9: =IFERROR(IF(E9="Long",(IF(AND(B9="Closed",AD9<>""),AD9,O9)-G9)*H9*I9,(G9-IF(AND(B9="Closed",AD9<>""),AD9,O9))*H9*I9),"") -> 4.08384e+08 | R9: =IFERROR(Q9/(G9*H9),"") -> 0.49984529 | S9: =IFERROR(L9/(IFERROR(LOOKUP(2,1/('Transaction Log'!H5:H106<>""),'Transaction Log'!H5:H106),0)),"") -> 0.39854673 | T9: 46091 | U9: =IFERROR(IF(B9="Closed",T9-F9,TODAY()-F9),"") -> 1 | V9: 5058 | W9: 5234 | X9: =IFERROR(IF(OR(V9="",I9=""),"—",IF(E9="Long",(G9-V9)*H9*I9,(V9-G9)*H9*I9)),"—") -> 1.54816e+08 | Y9: =IFERROR(IF(OR(V9="",G9=""),"—",IF(E9="Long",(G9-V9)/G9,(V9-G9)/G9)),"—") -> 0.0094744222 | Z9: =IFERROR(IF(OR(W9="",I9=""),"—",IF(E9="Long",(W9-G9)*H9*I9,(G9-W9)*H9*I9)),"—") -> 4.08384e+08 | AA9: =IFERROR(IF(OR(W9="",G9=""),"—",IF(E9="Long",(W9-G9)/G9,(G9-W9)/G9)),"—") -> 0.024992265 | AB9: Additional position Long on Gold market opening Monday | AC9: =IFERROR(IF(E9="Long",(G9-V9)*H9*I9,(V9-G9)*H9*I9),"") -> 1.54816e+08 | AD9: =IFERROR(IF(OR(AF9="STOP LOSS HIT",AF9="TAKE PROFIT HIT"),AG9,""),"") -> 5234 | AE9: =IFERROR(IF(E9="Long",(IF(AND(B9="Closed",AD9<>""),AD9,O9)-G9)/G9,(G9-IF(AND(B9="Closed",AD9<>""),AD9,O9))/G9),"") -> 0.024992265 | AF9: =IFERROR(IF(OR(V9="",W9=""),"No SL/TP",IF(E9="Long",IF(O9<=V9,"STOP LOSS HIT",IF(O9>=W9,"TAKE PROFIT HIT",IF(B9="Closed","CLOSED","Active"))),IF(O9>=V9,"STOP LOSS HIT",IF(O9<=W9,"TAKE PROFIT HIT",IF(B9="Closed","CLOSED","Active"))))),"—") -> TAKE PROFIT HIT | AG9: =IFERROR(IF(E9="Long",IF(O9<=V9,V9,IF(O9>=W9,W9,"")),IF(O9>=V9,V9,IF(O9<=W9,W9,""))),"") -> 5234 | AH9: =IFERROR(IF(B9<>"Open","—",IF(E9="Long",G9*(1-1/I9),G9*(1+1/I9))),"—") -> —
A10: =IFERROR(ROW()-5,"") -> 5 | B10: Closed | C10: Forex | D10: AUD/USD | E10: Short | F10: 46090 | G10: 0.77852 | H10: 500000000 | I10: 15 | J10: =IFERROR(1/I10,"") -> 0.066666667 | K10: =IFERROR(G10*H10*I10,"") -> 5838900000 | L10: =IFERROR(G10*H10,"") -> 389260000 | M10: 0.5 | N10: =IFERROR(IF(B10<>"Open","—",IF((G10*H10+Q10)<=0,"LIQUIDATION",IF((G10*H10+Q10)/(G10*H10)<=M10,"WARNING","OK"))),"—") -> — | O10: 0.7759 | P10: =IFERROR((IF(AND(B10="Closed",AD10<>""),AD10,O10))*H10,"") -> 387950000 | Q10: =IFERROR(IF(E10="Long",(IF(AND(B10="Closed",AD10<>""),AD10,O10)-G10)*H10*I10,(G10-IF(AND(B10="Closed",AD10<>""),AD10,O10))*H10*I10),"") -> 19650000 | R10: =IFERROR(Q10/(G10*H10),"") -> 0.050480399 | S10: =IFERROR(L10/(IFERROR(LOOKUP(2,1/('Transaction Log'!H5:H106<>""),'Transaction Log'!H5:H106),0)),"") -> 0.18988293 | T10: 46091 | U10: =IFERROR(IF(B10="Closed",T10-F10,TODAY()-F10),"") -> 1 | V10: 0.782 | W10: 0.7759 | X10: =IFERROR(IF(OR(V10="",I10=""),"—",IF(E10="Long",(G10-V10)*H10*I10,(V10-G10)*H10*I10)),"—") -> 26100000 | Y10: =IFERROR(IF(OR(V10="",G10=""),"—",IF(E10="Long",(G10-V10)/G10,(V10-G10)/G10)),"—") -> 0.00447002 | Z10: =IFERROR(IF(OR(W10="",I10=""),"—",IF(E10="Long",(W10-G10)*H10*I10,(G10-W10)*H10*I10)),"—") -> 19650000 | AA10: =IFERROR(IF(OR(W10="",G10=""),"—",IF(E10="Long",(W10-G10)/G10,(G10-W10)/G10)),"—") -> 0.0033653599 | AB10: Inverse relationship with gold complementary trade | AC10: =IFERROR(IF(E10="Long",(G10-V10)*H10*I10,(V10-G10)*H10*I10),"") -> 26100000 | AD10: =IFERROR(IF(OR(AF10="STOP LOSS HIT",AF10="TAKE PROFIT HIT"),AG10,""),"") -> 0.7759 | AE10: =IFERROR(IF(E10="Long",(IF(AND(B10="Closed",AD10<>""),AD10,O10)-G10)/G10,(G10-IF(AND(B10="Closed",AD10<>""),AD10,O10))/G10),"") -> 0.0033653599 | AF10: =IFERROR(IF(OR(V10="",W10=""),"No SL/TP",IF(E10="Long",IF(O10<=V10,"STOP LOSS HIT",IF(O10>=W10,"TAKE PROFIT HIT",IF(B10="Closed","CLOSED","Active"))),IF(O10>=V10,"STOP LOSS HIT",IF(O10<=W10,"TAKE PROFIT HIT",IF(B10="Closed","CLOSED","Active"))))),"—") -> TAKE PROFIT HIT | AG10: =IFERROR(IF(E10="Long",IF(O10<=V10,V10,IF(O10>=W10,W10,"")),IF(O10>=V10,V10,IF(O10<=W10,W10,""))),"") -> 0.7759 | AH10: =IFERROR(IF(B10<>"Open","—",IF(E10="Long",G10*(1-1/I10),G10*(1+1/I10))),"—") -> —
A11: =IFERROR(ROW()-5,"") -> 6 | B11: Closed | C11: Futures | D11: Gold | E11: Long | F11: 46087 | G11: 5078 | H11: 140000 | I11: 20 | J11: =IFERROR(1/I11,"") -> 0.05 | K11: =IFERROR(G11*H11*I11,"") -> 14218400000 | L11: =IFERROR(G11*H11,"") -> 710920000 | M11: 0.5 | N11: =IFERROR(IF(B11<>"Open","—",IF((G11*H11+Q11)<=0,"LIQUIDATION",IF((G11*H11+Q11)/(G11*H11)<=M11,"WARNING","OK"))),"—") -> — | O11: 5172 | P11: =IFERROR((IF(AND(B11="Closed",AD11<>""),AD11,O11))*H11,"") -> 724080000 | Q11: =IFERROR(IF(E11="Long",(IF(AND(B11="Closed",AD11<>""),AD11,O11)-G11)*H11*I11,(G11-IF(AND(B11="Closed",AD11<>""),AD11,O11))*H11*I11),"") -> 263200000 | R11: =IFERROR(Q11/(G11*H11),"") -> 0.3702245 | S11: =IFERROR(L11/(IFERROR(LOOKUP(2,1/('Transaction Log'!H5:H106<>""),'Transaction Log'!H5:H106),0)),"") -> 0.34679024 | T11: 46087 | U11: =IFERROR(IF(B11="Closed",T11-F11,TODAY()-F11),"") -> 0 | V11: 5050 | W11: 5172 | X11: =IFERROR(IF(OR(V11="",I11=""),"—",IF(E11="Long",(G11-V11)*H11*I11,(V11-G11)*H11*I11)),"—") -> 78400000 | Y11: =IFERROR(IF(OR(V11="",G11=""),"—",IF(E11="Long",(G11-V11)/G11,(V11-G11)/G11)),"—") -> 0.0055139819 | Z11: =IFERROR(IF(OR(W11="",I11=""),"—",IF(E11="Long",(W11-G11)*H11*I11,(G11-W11)*H11*I11)),"—") -> 263200000 | AA11: =IFERROR(IF(OR(W11="",G11=""),"—",IF(E11="Long",(W11-G11)/G11,(G11-W11)/G11)),"—") -> 0.018511225 | AB11: Geopo-leads to investing in safe assets HOLD | AC11: =IFERROR(IF(E11="Long",(G11-V11)*H11*I11,(V11-G11)*H11*I11),"") -> 78400000 | AD11: =IFERROR(IF(OR(AF11="STOP LOSS HIT",AF11="TAKE PROFIT HIT"),AG11,""),"") -> 5172 | AE11: =IFERROR(IF(E11="Long",(IF(AND(B11="Closed",AD11<>""),AD11,O11)-G11)/G11,(G11-IF(AND(B11="Closed",AD11<>""),AD11,O11))/G11),"") -> 0.018511225 | AF11: =IFERROR(IF(OR(V11="",W11=""),"No SL/TP",IF(E11="Long",IF(O11<=V11,"STOP LOSS HIT",IF(O11>=W11,"TAKE PROFIT HIT",IF(B11="Closed","CLOSED","Active"))),IF(O11>=V11,"STOP LOSS HIT",IF(O11<=W11,"TAKE PROFIT HIT",IF(B11="Closed","CLOSED","Active"))))),"—") -> TAKE PROFIT HIT | AG11: =IFERROR(IF(E11="Long",IF(O11<=V11,V11,IF(O11>=W11,W11,"")),IF(O11>=V11,V11,IF(O11<=W11,W11,""))),"") -> 5172 | AH11: =IFERROR(IF(B11<>"Open","—",IF(E11="Long",G11*(1-1/I11),G11*(1+1/I11))),"—") -> —
A12: =IFERROR(ROW()-5,"") -> 7 | B12: Closed | C12: Crypto | D12: BTC | E12: Long | F12: 46087 | G12: 70509.74 | H12: 15000 | I12: 20 | J12: =IFERROR(1/I12,"") -> 0.05 | K12: =IFERROR(G12*H12*I12,"") -> 2.1152922e+10 | L12: =IFERROR(G12*H12,"") -> 1.0576461e+09 | M12: 0.5 | N12: =IFERROR(IF(B12<>"Open","—",IF((G12*H12+Q12)<=0,"LIQUIDATION",IF((G12*H12+Q12)/(G12*H12)<=M12,"WARNING","OK"))),"—") -> — | O12: 71230 | P12: =IFERROR((IF(AND(B12="Closed",AD12<>""),AD12,O12))*H12,"") -> 1068450000 | Q12: =IFERROR(IF(E12="Long",(IF(AND(B12="Closed",AD12<>""),AD12,O12)-G12)*H12*I12,(G12-IF(AND(B12="Closed",AD12<>""),AD12,O12))*H12*I12),"") -> 2.16078e+08 | R12: =IFERROR(Q12/(G12*H12),"") -> 0.20430085 | S12: =IFERROR(L12/(IFERROR(LOOKUP(2,1/('Transaction Log'!H5:H106<>""),'Transaction Log'!H5:H106),0)),"") -> 0.51592493 | T12: 46087 | U12: =IFERROR(IF(B12="Closed",T12-F12,TODAY()-F12),"") -> 0 | V12: 68950 | W12: 71230 | X12: =IFERROR(IF(OR(V12="",I12=""),"—",IF(E12="Long",(G12-V12)*H12*I12,(V12-G12)*H12*I12)),"—") -> 4.67922e+08 | Y12: =IFERROR(IF(OR(V12="",G12=""),"—",IF(E12="Long",(G12-V12)/G12,(V12-G12)/G12)),"—") -> 0.022120915 | Z12: =IFERROR(IF(OR(W12="",I12=""),"—",IF(E12="Long",(W12-G12)*H12*I12,(G12-W12)*H12*I12)),"—") -> 2.16078e+08 | AA12: =IFERROR(IF(OR(W12="",G12=""),"—",IF(E12="Long",(W12-G12)/G12,(G12-W12)/G12)),"—") -> 0.010215043 | AB12: BTC big drawback, must restore resistance and buy volume rallying up price | AC12: =IFERROR(IF(E12="Long",(G12-V12)*H12*I12,(V12-G12)*H12*I12),"") -> 4.67922e+08 | AD12: =IFERROR(IF(OR(AF12="STOP LOSS HIT",AF12="TAKE PROFIT HIT"),AG12,""),"") -> 71230 | AE12: =IFERROR(IF(E12="Long",(IF(AND(B12="Closed",AD12<>""),AD12,O12)-G12)/G12,(G12-IF(AND(B12="Closed",AD12<>""),AD12,O12))/G12),"") -> 0.010215043 | AF12: =IFERROR(IF(OR(V12="",W12=""),"No SL/TP",IF(E12="Long",IF(O12<=V12,"STOP LOSS HIT",IF(O12>=W12,"TAKE PROFIT HIT",IF(B12="Closed","CLOSED","Active"))),IF(O12>=V12,"STOP LOSS HIT",IF(O12<=W12,"TAKE PROFIT HIT",IF(B12="Closed","CLOSED","Active"))))),"—") -> TAKE PROFIT HIT | AG12: =IFERROR(IF(E12="Long",IF(O12<=V12,V12,IF(O12>=W12,W12,"")),IF(O12>=V12,V12,IF(O12<=W12,W12,""))),"") -> 71230 | AH12: =IFERROR(IF(B12<>"Open","—",IF(E12="Long",G12*(1-1/I12),G12*(1+1/I12))),"—") -> —
A13: =IFERROR(ROW()-5,"") -> 8 | B13: Closed | C13: Futures | D13: Oil | E13: Long | F13: 46087 | G13: 78.585 | H13: 500000 | I13: 10 | J13: =IFERROR(1/I13,"") -> 0.1 | K13: =IFERROR(G13*H13*I13,"") -> 392925000 | L13: =IFERROR(G13*H13,"") -> 39292500 | M13: 0.5 | N13: =IFERROR(IF(B13<>"Open","—",IF((G13*H13+Q13)<=0,"LIQUIDATION",IF((G13*H13+Q13)/(G13*H13)<=M13,"WARNING","OK"))),"—") -> — | O13: 86.28 | P13: =IFERROR((IF(AND(B13="Closed",AD13<>""),AD13,O13))*H13,"") -> 43140000 | Q13: =IFERROR(IF(E13="Long",(IF(AND(B13="Closed",AD13<>""),AD13,O13)-G13)*H13*I13,(G13-IF(AND(B13="Closed",AD13<>""),AD13,O13))*H13*I13),"") -> 38475000 | R13: =IFERROR(Q13/(G13*H13),"") -> 0.9791945 | S13: =IFERROR(L13/(IFERROR(LOOKUP(2,1/('Transaction Log'!H5:H106<>""),'Transaction Log'!H5:H106),0)),"") -> 0.019167073 | T13: 46087 | U13: =IFERROR(IF(B13="Closed",T13-F13,TODAY()-F13),"") -> 0 | V13: 76.35 | W13: 86.28 | X13: =IFERROR(IF(OR(V13="",I13=""),"—",IF(E13="Long",(G13-V13)*H13*I13,(V13-G13)*H13*I13)),"—") -> 11175000 | Y13: =IFERROR(IF(OR(V13="",G13=""),"—",IF(E13="Long",(G13-V13)/G13,(V13-G13)/G13)),"—") -> 0.028440542 | Z13: =IFERROR(IF(OR(W13="",I13=""),"—",IF(E13="Long",(W13-G13)*H13*I13,(G13-W13)*H13*I13)),"—") -> 38475000 | AA13: =IFERROR(IF(OR(W13="",G13=""),"—",IF(E13="Long",(W13-G13)/G13,(G13-W13)/G13)),"—") -> 0.09791945 | AB13: Continued burden on closing of straight of Hormuz | AC13: =IFERROR(IF(E13="Long",(G13-V13)*H13*I13,(V13-G13)*H13*I13),"") -> 11175000 | AD13: =IFERROR(IF(OR(AF13="STOP LOSS HIT",AF13="TAKE PROFIT HIT"),AG13,""),"") -> 86.28 | AE13: =IFERROR(IF(E13="Long",(IF(AND(B13="Closed",AD13<>""),AD13,O13)-G13)/G13,(G13-IF(AND(B13="Closed",AD13<>""),AD13,O13))/G13),"") -> 0.09791945 | AF13: =IFERROR(IF(OR(V13="",W13=""),"No SL/TP",IF(E13="Long",IF(O13<=V13,"STOP LOSS HIT",IF(O13>=W13,"TAKE PROFIT HIT",IF(B13="Closed","CLOSED","Active"))),IF(O13>=V13,"STOP LOSS HIT",IF(O13<=W13,"TAKE PROFIT HIT",IF(B13="Closed","CLOSED","Active"))))),"—") -> TAKE PROFIT HIT | AG13: =IFERROR(IF(E13="Long",IF(O13<=V13,V13,IF(O13>=W13,W13,"")),IF(O13>=V13,V13,IF(O13<=W13,W13,""))),"") -> 86.28 | AH13: =IFERROR(IF(B13<>"Open","—",IF(E13="Long",G13*(1-1/I13),G13*(1+1/I13))),"—") -> —
A14: =IFERROR(ROW()-5,"") -> 9 | B14: Closed | C14: Crypto | D14: BTC | E14: Short | F14: 46087 | G14: 70755.2 | H14: 7200 | I14: 20 | J14: =IFERROR(1/I14,"") -> 0.05 | K14: =IFERROR(G14*H14*I14,"") -> 10188748800 | L14: =IFERROR(G14*H14,"") -> 509437440 | M14: 0.5 | N14: =IFERROR(IF(B14<>"Open","—",IF((G14*H14+Q14)<=0,"LIQUIDATION",IF((G14*H14+Q14)/(G14*H14)<=M14,"WARNING","OK"))),"—") -> — | O14: 69975 | P14: =IFERROR((IF(AND(B14="Closed",AD14<>""),AD14,O14))*H14,"") -> 503820000 | Q14: =IFERROR(IF(E14="Long",(IF(AND(B14="Closed",AD14<>""),AD14,O14)-G14)*H14*I14,(G14-IF(AND(B14="Closed",AD14<>""),AD14,O14))*H14*I14),"") -> 1.123488e+08 | R14: =IFERROR(Q14/(G14*H14),"") -> 0.22053503 | S14: =IFERROR(L14/(IFERROR(LOOKUP(2,1/('Transaction Log'!H5:H106<>""),'Transaction Log'!H5:H106),0)),"") -> 0.24850607 | T14: 46087 | U14: =IFERROR(IF(B14="Closed",T14-F14,TODAY()-F14),"") -> 0 | V14: 71445 | W14: 69975 | X14: =IFERROR(IF(OR(V14="",I14=""),"—",IF(E14="Long",(G14-V14)*H14*I14,(V14-G14)*H14*I14)),"—") -> 99331200 | Y14: =IFERROR(IF(OR(V14="",G14=""),"—",IF(E14="Long",(G14-V14)/G14,(V14-G14)/G14)),"—") -> 0.0097491068 | Z14: =IFERROR(IF(OR(W14="",I14=""),"—",IF(E14="Long",(W14-G14)*H14*I14,(G14-W14)*H14*I14)),"—") -> 1.123488e+08 | AA14: =IFERROR(IF(OR(W14="",G14=""),"—",IF(E14="Long",(W14-G14)/G14,(G14-W14)/G14)),"—") -> 0.011026751 | AB14: BTC Bear swing sentiment - projected 40k support level | AC14: =IFERROR(IF(E14="Long",(G14-V14)*H14*I14,(V14-G14)*H14*I14),"") -> 99331200 | AD14: =IFERROR(IF(OR(AF14="STOP LOSS HIT",AF14="TAKE PROFIT HIT"),AG14,""),"") -> 69975 | AE14: =IFERROR(IF(E14="Long",(IF(AND(B14="Closed",AD14<>""),AD14,O14)-G14)/G14,(G14-IF(AND(B14="Closed",AD14<>""),AD14,O14))/G14),"") -> 0.011026751 | AF14: =IFERROR(IF(OR(V14="",W14=""),"No SL/TP",IF(E14="Long",IF(O14<=V14,"STOP LOSS HIT",IF(O14>=W14,"TAKE PROFIT HIT",IF(B14="Closed","CLOSED","Active"))),IF(O14>=V14,"STOP LOSS HIT",IF(O14<=W14,"TAKE PROFIT HIT",IF(B14="Closed","CLOSED","Active"))))),"—") -> TAKE PROFIT HIT | AG14: =IFERROR(IF(E14="Long",IF(O14<=V14,V14,IF(O14>=W14,W14,"")),IF(O14>=V14,V14,IF(O14<=W14,W14,""))),"") -> 69975 | AH14: =IFERROR(IF(B14<>"Open","—",IF(E14="Long",G14*(1-1/I14),G14*(1+1/I14))),"—") -> —
A15: =IFERROR(ROW()-5,"") -> 10 | B15: Closed | C15: Futures | D15: Oil | E15: Long | F15: 46087 | G15: 85.43 | H15: 15000 | I15: 20 | J15: =IFERROR(1/I15,"") -> 0.05 | K15: =IFERROR(G15*H15*I15,"") -> 25629000 | L15: =IFERROR(G15*H15,"") -> 1281450 | M15: 0.5 | N15: =IFERROR(IF(B15<>"Open","—",IF((G15*H15+Q15)<=0,"LIQUIDATION",IF((G15*H15+Q15)/(G15*H15)<=M15,"WARNING","OK"))),"—") -> — | O15: 90.16 | P15: =IFERROR((IF(AND(B15="Closed",AD15<>""),AD15,O15))*H15,"") -> 1352400 | Q15: =IFERROR(IF(E15="Long",(IF(AND(B15="Closed",AD15<>""),AD15,O15)-G15)*H15*I15,(G15-IF(AND(B15="Closed",AD15<>""),AD15,O15))*H15*I15),"") -> 1419000 | R15: =IFERROR(Q15/(G15*H15),"") -> 1.1073393 | S15: =IFERROR(L15/(IFERROR(LOOKUP(2,1/('Transaction Log'!H5:H106<>""),'Transaction Log'!H5:H106),0)),"") -> 0.00062509756 | T15: 46088 | U15: =IFERROR(IF(B15="Closed",T15-F15,TODAY()-F15),"") -> 1 | V15: 84.78 | W15: 90.16 | X15: =IFERROR(IF(OR(V15="",I15=""),"—",IF(E15="Long",(G15-V15)*H15*I15,(V15-G15)*H15*I15)),"—") -> 195000 | Y15: =IFERROR(IF(OR(V15="",G15=""),"—",IF(E15="Long",(G15-V15)/G15,(V15-G15)/G15)),"—") -> 0.0076085684 | Z15: =IFERROR(IF(OR(W15="",I15=""),"—",IF(E15="Long",(W15-G15)*H15*I15,(G15-W15)*H15*I15)),"—") -> 1419000 | AA15: =IFERROR(IF(OR(W15="",G15=""),"—",IF(E15="Long",(W15-G15)/G15,(G15-W15)/G15)),"—") -> 0.055366967 | AB15: New Long Hold on Oil until TP, distanced SL to avoid volatility | AC15: =IFERROR(IF(E15="Long",(G15-V15)*H15*I15,(V15-G15)*H15*I15),"") -> 195000 | AD15: =IFERROR(IF(OR(AF15="STOP LOSS HIT",AF15="TAKE PROFIT HIT"),AG15,""),"") -> 90.16 | AE15: =IFERROR(IF(E15="Long",(IF(AND(B15="Closed",AD15<>""),AD15,O15)-G15)/G15,(G15-IF(AND(B15="Closed",AD15<>""),AD15,O15))/G15),"") -> 0.055366967 | AF15: =IFERROR(IF(OR(V15="",W15=""),"No SL/TP",IF(E15="Long",IF(O15<=V15,"STOP LOSS HIT",IF(O15>=W15,"TAKE PROFIT HIT",IF(B15="Closed","CLOSED","Active"))),IF(O15>=V15,"STOP LOSS HIT",IF(O15<=W15,"TAKE PROFIT HIT",IF(B15="Closed","CLOSED","Active"))))),"—") -> TAKE PROFIT HIT | AG15: =IFERROR(IF(E15="Long",IF(O15<=V15,V15,IF(O15>=W15,W15,"")),IF(O15>=V15,V15,IF(O15<=W15,W15,""))),"") -> 90.16 | AH15: =IFERROR(IF(B15<>"Open","—",IF(E15="Long",G15*(1-1/I15),G15*(1+1/I15))),"—") -> —
A16: =IFERROR(ROW()-5,"") -> 11 | B16: Closed | C16: Futures | D16: Oil | E16: Long | F16: 46087 | G16: 87.13 | H16: 25000 | I16: 10 | J16: =IFERROR(1/I16,"") -> 0.1 | K16: =IFERROR(G16*H16*I16,"") -> 21782500 | L16: =IFERROR(G16*H16,"") -> 2178250 | M16: 0.5 | N16: =IFERROR(IF(B16<>"Open","—",IF((G16*H16+Q16)<=0,"LIQUIDATION",IF((G16*H16+Q16)/(G16*H16)<=M16,"WARNING","OK"))),"—") -> — | O16: 96.49 | P16: =IFERROR((IF(AND(B16="Closed",AD16<>""),AD16,O16))*H16,"") -> 2412250 | Q16: =IFERROR(IF(E16="Long",(IF(AND(B16="Closed",AD16<>""),AD16,O16)-G16)*H16*I16,(G16-IF(AND(B16="Closed",AD16<>""),AD16,O16))*H16*I16),"") -> 2340000 | R16: =IFERROR(Q16/(G16*H16),"") -> 1.0742569 | S16: =IFERROR(L16/(IFERROR(LOOKUP(2,1/('Transaction Log'!H5:H106<>""),'Transaction Log'!H5:H106),0)),"") -> 0.001062561 | T16: 46090 | U16: =IFERROR(IF(B16="Closed",T16-F16,TODAY()-F16),"") -> 3 | V16: 84.24 | W16: 96.49 | X16: =IFERROR(IF(OR(V16="",I16=""),"—",IF(E16="Long",(G16-V16)*H16*I16,(V16-G16)*H16*I16)),"—") -> 722500 | Y16: =IFERROR(IF(OR(V16="",G16=""),"—",IF(E16="Long",(G16-V16)/G16,(V16-G16)/G16)),"—") -> 0.033168828 | Z16: =IFERROR(IF(OR(W16="",I16=""),"—",IF(E16="Long",(W16-G16)*H16*I16,(G16-W16)*H16*I16)),"—") -> 2340000 | AA16: =IFERROR(IF(OR(W16="",G16=""),"—",IF(E16="Long",(W16-G16)/G16,(G16-W16)/G16)),"—") -> 0.10742569 | AB16: Added position to amplify gains, higher TP lower Leverage | AC16: =IFERROR(IF(E16="Long",(G16-V16)*H16*I16,(V16-G16)*H16*I16),"") -> 722500 | AD16: =IFERROR(IF(OR(AF16="STOP LOSS HIT",AF16="TAKE PROFIT HIT"),AG16,""),"") -> 96.49 | AE16: =IFERROR(IF(E16="Long",(IF(AND(B16="Closed",AD16<>""),AD16,O16)-G16)/G16,(G16-IF(AND(B16="Closed",AD16<>""),AD16,O16))/G16),"") -> 0.10742569 | AF16: =IFERROR(IF(OR(V16="",W16=""),"No SL/TP",IF(E16="Long",IF(O16<=V16,"STOP LOSS HIT",IF(O16>=W16,"TAKE PROFIT HIT",IF(B16="Closed","CLOSED","Active"))),IF(O16>=V16,"STOP LOSS HIT",IF(O16<=W16,"TAKE PROFIT HIT",IF(B16="Closed","CLOSED","Active"))))),"—") -> TAKE PROFIT HIT | AG16: =IFERROR(IF(E16="Long",IF(O16<=V16,V16,IF(O16>=W16,W16,"")),IF(O16>=V16,V16,IF(O16<=W16,W16,""))),"") -> 96.49 | AH16: =IFERROR(IF(B16<>"Open","—",IF(E16="Long",G16*(1-1/I16),G16*(1+1/I16))),"—") -> —
A17: =IFERROR(ROW()-5,"") -> 12 | B17: Closed | C17: Index | D17: Nikkei 225 | E17: Short | F17: 46087 | G17: 22748.986 | H17: 18000 | I17: 10 | J17: =IFERROR(1/I17,"") -> 0.1 | K17: =IFERROR(G17*H17*I17,"") -> 4094817480 | L17: =IFERROR(G17*H17,"") -> 409481748 | M17: 0.5 | N17: =IFERROR(IF(B17<>"Open","—",IF((G17*H17+Q17)<=0,"LIQUIDATION",IF((G17*H17+Q17)/(G17*H17)<=M17,"WARNING","OK"))),"—") -> — | O17: 22387.679 | P17: =IFERROR((IF(AND(B17="Closed",AD17<>""),AD17,O17))*H17,"") -> 402978222 | Q17: =IFERROR(IF(E17="Long",(IF(AND(B17="Closed",AD17<>""),AD17,O17)-G17)*H17*I17,(G17-IF(AND(B17="Closed",AD17<>""),AD17,O17))*H17*I17),"") -> 65035260 | R17: =IFERROR(Q17/(G17*H17),"") -> 0.15882334 | S17: =IFERROR(L17/(IFERROR(LOOKUP(2,1/('Transaction Log'!H5:H106<>""),'Transaction Log'!H5:H106),0)),"") -> 0.19974719 | T17: 46090 | U17: =IFERROR(IF(B17="Closed",T17-F17,TODAY()-F17),"") -> 3 | V17: 23258 | W17: 22324 | X17: =IFERROR(IF(OR(V17="",I17=""),"—",IF(E17="Long",(G17-V17)*H17*I17,(V17-G17)*H17*I17)),"—") -> 91622520 | Y17: =IFERROR(IF(OR(V17="",G17=""),"—",IF(E17="Long",(G17-V17)/G17,(V17-G17)/G17)),"—") -> 0.022375239 | Z17: =IFERROR(IF(OR(W17="",I17=""),"—",IF(E17="Long",(W17-G17)*H17*I17,(G17-W17)*H17*I17)),"—") -> 76497480 | AA17: =IFERROR(IF(OR(W17="",G17=""),"—",IF(E17="Long",(W17-G17)/G17,(G17-W17)/G17)),"—") -> 0.018681536 | AB17: Growing fear in US market over war | AC17: =IFERROR(IF(E17="Long",(G17-V17)*H17*I17,(V17-G17)*H17*I17),"") -> 91622520 | AD17: =IFERROR(IF(OR(AF17="STOP LOSS HIT",AF17="TAKE PROFIT HIT"),AG17,""),"") | AE17: =IFERROR(IF(E17="Long",(IF(AND(B17="Closed",AD17<>""),AD17,O17)-G17)/G17,(G17-IF(AND(B17="Closed",AD17<>""),AD17,O17))/G17),"") -> 0.015882334 | AF17: =IFERROR(IF(OR(V17="",W17=""),"No SL/TP",IF(E17="Long",IF(O17<=V17,"STOP LOSS HIT",IF(O17>=W17,"TAKE PROFIT HIT",IF(B17="Closed","CLOSED","Active"))),IF(O17>=V17,"STOP LOSS HIT",IF(O17<=W17,"TAKE PROFIT HIT",IF(B17="Closed","CLOSED","Active"))))),"—") -> CLOSED | AG17: =IFERROR(IF(E17="Long",IF(O17<=V17,V17,IF(O17>=W17,W17,"")),IF(O17>=V17,V17,IF(O17<=W17,W17,""))),"") | AH17: =IFERROR(IF(B17<>"Open","—",IF(E17="Long",G17*(1-1/I17),G17*(1+1/I17))),"—") -> —
A18: =IFERROR(ROW()-5,"") -> 13 | B18: Closed | C18: Forex | D18: AUD/USD | E18: Short | F18: 46087 | G18: 0.7817 | H18: 400000000 | I18: 10 | J18: =IFERROR(1/I18,"") -> 0.1 | K18: =IFERROR(G18*H18*I18,"") -> 3126800000 | L18: =IFERROR(G18*H18,"") -> 312680000 | M18: 0.5 | N18: =IFERROR(IF(B18<>"Open","—",IF((G18*H18+Q18)<=0,"LIQUIDATION",IF((G18*H18+Q18)/(G18*H18)<=M18,"WARNING","OK"))),"—") -> — | O18: 0.776 | P18: =IFERROR((IF(AND(B18="Closed",AD18<>""),AD18,O18))*H18,"") -> 310400000 | Q18: =IFERROR(IF(E18="Long",(IF(AND(B18="Closed",AD18<>""),AD18,O18)-G18)*H18*I18,(G18-IF(AND(B18="Closed",AD18<>""),AD18,O18))*H18*I18),"") -> 22800000 | R18: =IFERROR(Q18/(G18*H18),"") -> 0.072917999 | S18: =IFERROR(L18/(IFERROR(LOOKUP(2,1/('Transaction Log'!H5:H106<>""),'Transaction Log'!H5:H106),0)),"") -> 0.15252683 | T18: 46087 | U18: =IFERROR(IF(B18="Closed",T18-F18,TODAY()-F18),"") -> 0 | V18: 0.7858 | W18: 0.776 | X18: =IFERROR(IF(OR(V18="",I18=""),"—",IF(E18="Long",(G18-V18)*H18*I18,(V18-G18)*H18*I18)),"—") -> 16400000 | Y18: =IFERROR(IF(OR(V18="",G18=""),"—",IF(E18="Long",(G18-V18)/G18,(V18-G18)/G18)),"—") -> 0.0052449789 | Z18: =IFERROR(IF(OR(W18="",I18=""),"—",IF(E18="Long",(W18-G18)*H18*I18,(G18-W18)*H18*I18)),"—") -> 22800000 | AA18: =IFERROR(IF(OR(W18="",G18=""),"—",IF(E18="Long",(W18-G18)/G18,(G18-W18)/G18)),"—") -> 0.0072917999 | AB18: Bearish outlook on USD appreciation with investors rushing to safe assets | AC18: =IFERROR(IF(E18="Long",(G18-V18)*H18*I18,(V18-G18)*H18*I18),"") -> 16400000 | AD18: =IFERROR(IF(OR(AF18="STOP LOSS HIT",AF18="TAKE PROFIT HIT"),AG18,""),"") -> 0.776 | AE18: =IFERROR(IF(E18="Long",(IF(AND(B18="Closed",AD18<>""),AD18,O18)-G18)/G18,(G18-IF(AND(B18="Closed",AD18<>""),AD18,O18))/G18),"") -> 0.0072917999 | AF18: =IFERROR(IF(OR(V18="",W18=""),"No SL/TP",IF(E18="Long",IF(O18<=V18,"STOP LOSS HIT",IF(O18>=W18,"TAKE PROFIT HIT",IF(B18="Closed","CLOSED","Active"))),IF(O18>=V18,"STOP LOSS HIT",IF(O18<=W18,"TAKE PROFIT HIT",IF(B18="Closed","CLOSED","Active"))))),"—") -> TAKE PROFIT HIT | AG18: =IFERROR(IF(E18="Long",IF(O18<=V18,V18,IF(O18>=W18,W18,"")),IF(O18>=V18,V18,IF(O18<=W18,W18,""))),"") -> 0.776 | AH18: =IFERROR(IF(B18<>"Open","—",IF(E18="Long",G18*(1-1/I18),G18*(1+1/I18))),"—") -> —
A19: =IFERROR(ROW()-5,"") -> 14 | B19: Closed | C19: Stock | D19: AMZN | E19: Long | F19: 46086 | G19: 212.415 | H19: 1500000 | I19: 10 | J19: =IFERROR(1/I19,"") -> 0.1 | K19: =IFERROR(G19*H19*I19,"") -> 3186225000 | L19: =IFERROR(G19*H19,"") -> 318622500 | M19: 0.5 | N19: =IFERROR(IF(B19<>"Open","—",IF((G19*H19+Q19)<=0,"LIQUIDATION",IF((G19*H19+Q19)/(G19*H19)<=M19,"WARNING","OK"))),"—") -> — | O19: 214.5 | P19: =IFERROR((IF(AND(B19="Closed",AD19<>""),AD19,O19))*H19,"") -> 321750000 | Q19: =IFERROR(IF(E19="Long",(IF(AND(B19="Closed",AD19<>""),AD19,O19)-G19)*H19*I19,(G19-IF(AND(B19="Closed",AD19<>""),AD19,O19))*H19*I19),"") -> 31275000 | R19: =IFERROR(Q19/(G19*H19),"") -> 0.09815691 | S19: =IFERROR(L19/(IFERROR(LOOKUP(2,1/('Transaction Log'!H5:H106<>""),'Transaction Log'!H5:H106),0)),"") -> 0.15542561 | T19: 46091 | U19: =IFERROR(IF(B19="Closed",T19-F19,TODAY()-F19),"") -> 5 | V19: 208 | W19: 214.5 | X19: =IFERROR(IF(OR(V19="",I19=""),"—",IF(E19="Long",(G19-V19)*H19*I19,(V19-G19)*H19*I19)),"—") -> 66225000 | Y19: =IFERROR(IF(OR(V19="",G19=""),"—",IF(E19="Long",(G19-V19)/G19,(V19-G19)/G19)),"—") -> 0.020784785 | Z19: =IFERROR(IF(OR(W19="",I19=""),"—",IF(E19="Long",(W19-G19)*H19*I19,(G19-W19)*H19*I19)),"—") -> 31275000 | AA19: =IFERROR(IF(OR(W19="",G19=""),"—",IF(E19="Long",(W19-G19)/G19,(G19-W19)/G19)),"—") -> 0.009815691 | AB19: Market volatility swing trade | AC19: =IFERROR(IF(E19="Long",(G19-V19)*H19*I19,(V19-G19)*H19*I19),"") -> 66225000 | AD19: =IFERROR(IF(OR(AF19="STOP LOSS HIT",AF19="TAKE PROFIT HIT"),AG19,""),"") -> 214.5 | AE19: =IFERROR(IF(E19="Long",(IF(AND(B19="Closed",AD19<>""),AD19,O19)-G19)/G19,(G19-IF(AND(B19="Closed",AD19<>""),AD19,O19))/G19),"") -> 0.009815691 | AF19: =IFERROR(IF(OR(V19="",W19=""),"No SL/TP",IF(E19="Long",IF(O19<=V19,"STOP LOSS HIT",IF(O19>=W19,"TAKE PROFIT HIT",IF(B19="Closed","CLOSED","Active"))),IF(O19>=V19,"STOP LOSS HIT",IF(O19<=W19,"TAKE PROFIT HIT",IF(B19="Closed","CLOSED","Active"))))),"—") -> TAKE PROFIT HIT | AG19: =IFERROR(IF(E19="Long",IF(O19<=V19,V19,IF(O19>=W19,W19,"")),IF(O19>=V19,V19,IF(O19<=W19,W19,""))),"") -> 214.5 | AH19: =IFERROR(IF(B19<>"Open","—",IF(E19="Long",G19*(1-1/I19),G19*(1+1/I19))),"—") -> —
A20: =IFERROR(ROW()-5,"") -> 15 | B20: Closed | C20: Crypto | D20: BTC | E20: Short | F20: 46086 | G20: 72775.14 | H20: 8000 | I20: 10 | J20: =IFERROR(1/I20,"") -> 0.1 | K20: =IFERROR(G20*H20*I20,"") -> 5822011200 | L20: =IFERROR(G20*H20,"") -> 582201120 | M20: 0.5 | N20: =IFERROR(IF(B20<>"Open","—",IF((G20*H20+Q20)<=0,"LIQUIDATION",IF((G20*H20+Q20)/(G20*H20)<=M20,"WARNING","OK"))),"—") -> — | O20: 72150 | P20: =IFERROR((IF(AND(B20="Closed",AD20<>""),AD20,O20))*H20,"") -> 577200000 | Q20: =IFERROR(IF(E20="Long",(IF(AND(B20="Closed",AD20<>""),AD20,O20)-G20)*H20*I20,(G20-IF(AND(B20="Closed",AD20<>""),AD20,O20))*H20*I20),"") -> 50011200 | R20: =IFERROR(Q20/(G20*H20),"") -> 0.085900213 | S20: =IFERROR(L20/(IFERROR(LOOKUP(2,1/('Transaction Log'!H5:H106<>""),'Transaction Log'!H5:H106),0)),"") -> 0.28400055 | T20: 46086 | U20: =IFERROR(IF(B20="Closed",T20-F20,TODAY()-F20),"") -> 0 | V20: 75240 | W20: 72150 | X20: =IFERROR(IF(OR(V20="",I20=""),"—",IF(E20="Long",(G20-V20)*H20*I20,(V20-G20)*H20*I20)),"—") -> 1.971888e+08 | Y20: =IFERROR(IF(OR(V20="",G20=""),"—",IF(E20="Long",(G20-V20)/G20,(V20-G20)/G20)),"—") -> 0.033869533 | Z20: =IFERROR(IF(OR(W20="",I20=""),"—",IF(E20="Long",(W20-G20)*H20*I20,(G20-W20)*H20*I20)),"—") -> 50011200 | AA20: =IFERROR(IF(OR(W20="",G20=""),"—",IF(E20="Long",(W20-G20)/G20,(G20-W20)/G20)),"—") -> 0.0085900213 | AB20: BTC SHORT POSITION HOLD | AC20: =IFERROR(IF(E20="Long",(G20-V20)*H20*I20,(V20-G20)*H20*I20),"") -> 1.971888e+08 | AD20: =IFERROR(IF(OR(AF20="STOP LOSS HIT",AF20="TAKE PROFIT HIT"),AG20,""),"") -> 72150 | AE20: =IFERROR(IF(E20="Long",(IF(AND(B20="Closed",AD20<>""),AD20,O20)-G20)/G20,(G20-IF(AND(B20="Closed",AD20<>""),AD20,O20))/G20),"") -> 0.0085900213 | AF20: =IFERROR(IF(OR(V20="",W20=""),"No SL/TP",IF(E20="Long",IF(O20<=V20,"STOP LOSS HIT",IF(O20>=W20,"TAKE PROFIT HIT",IF(B20="Closed","CLOSED","Active"))),IF(O20>=V20,"STOP LOSS HIT",IF(O20<=W20,"TAKE PROFIT HIT",IF(B20="Closed","CLOSED","Active"))))),"—") -> TAKE PROFIT HIT | AG20: =IFERROR(IF(E20="Long",IF(O20<=V20,V20,IF(O20>=W20,W20,"")),IF(O20>=V20,V20,IF(O20<=W20,W20,""))),"") -> 72150 | AH20: =IFERROR(IF(B20<>"Open","—",IF(E20="Long",G20*(1-1/I20),G20*(1+1/I20))),"—") -> —
A21: =IFERROR(ROW()-5,"") -> 16 | B21: Closed | C21: Stock | D21: NFLX | E21: Short | F21: 46086 | G21: 98.875 | H21: 6000000 | I21: 10 | J21: =IFERROR(1/I21,"") -> 0.1 | K21: =IFERROR(G21*H21*I21,"") -> 5932500000 | L21: =IFERROR(G21*H21,"") -> 593250000 | M21: 0.5 | N21: =IFERROR(IF(B21<>"Open","—",IF((G21*H21+Q21)<=0,"LIQUIDATION",IF((G21*H21+Q21)/(G21*H21)<=M21,"WARNING","OK"))),"—") -> — | O21: 98.1 | P21: =IFERROR((IF(AND(B21="Closed",AD21<>""),AD21,O21))*H21,"") -> 588600000 | Q21: =IFERROR(IF(E21="Long",(IF(AND(B21="Closed",AD21<>""),AD21,O21)-G21)*H21*I21,(G21-IF(AND(B21="Closed",AD21<>""),AD21,O21))*H21*I21),"") -> 46500000 | R21: =IFERROR(Q21/(G21*H21),"") -> 0.078381795 | S21: =IFERROR(L21/(IFERROR(LOOKUP(2,1/('Transaction Log'!H5:H106<>""),'Transaction Log'!H5:H106),0)),"") -> 0.28939024 | T21: 46086 | U21: =IFERROR(IF(B21="Closed",T21-F21,TODAY()-F21),"") -> 0 | V21: 99.43 | W21: 97.85 | X21: =IFERROR(IF(OR(V21="",I21=""),"—",IF(E21="Long",(G21-V21)*H21*I21,(V21-G21)*H21*I21)),"—") -> 33300000 | Y21: =IFERROR(IF(OR(V21="",G21=""),"—",IF(E21="Long",(G21-V21)/G21,(V21-G21)/G21)),"—") -> 0.0056131479 | Z21: =IFERROR(IF(OR(W21="",I21=""),"—",IF(E21="Long",(W21-G21)*H21*I21,(G21-W21)*H21*I21)),"—") -> 61500000 | AA21: =IFERROR(IF(OR(W21="",G21=""),"—",IF(E21="Long",(W21-G21)/G21,(G21-W21)/G21)),"—") -> 0.010366625 | AB21: Netflix Short position Day trade bearish sentiment | AC21: =IFERROR(IF(E21="Long",(G21-V21)*H21*I21,(V21-G21)*H21*I21),"") -> 33300000 | AD21: =IFERROR(IF(OR(AF21="STOP LOSS HIT",AF21="TAKE PROFIT HIT"),AG21,""),"") | AE21: =IFERROR(IF(E21="Long",(IF(AND(B21="Closed",AD21<>""),AD21,O21)-G21)/G21,(G21-IF(AND(B21="Closed",AD21<>""),AD21,O21))/G21),"") -> 0.0078381795 | AF21: =IFERROR(IF(OR(V21="",W21=""),"No SL/TP",IF(E21="Long",IF(O21<=V21,"STOP LOSS HIT",IF(O21>=W21,"TAKE PROFIT HIT",IF(B21="Closed","CLOSED","Active"))),IF(O21>=V21,"STOP LOSS HIT",IF(O21<=W21,"TAKE PROFIT HIT",IF(B21="Closed","CLOSED","Active"))))),"—") -> CLOSED | AG21: =IFERROR(IF(E21="Long",IF(O21<=V21,V21,IF(O21>=W21,W21,"")),IF(O21>=V21,V21,IF(O21<=W21,W21,""))),"") | AH21: =IFERROR(IF(B21<>"Open","—",IF(E21="Long",G21*(1-1/I21),G21*(1+1/I21))),"—") -> —
A22: =IFERROR(ROW()-5,"") -> 17 | B22: Closed | C22: Index | D22: S&P 500 | E22: Short | F22: 46086 | G22: 6869.5 | H22: 25000 | I22: 10 | J22: =IFERROR(1/I22,"") -> 0.1 | K22: =IFERROR(G22*H22*I22,"") -> 1717375000 | L22: =IFERROR(G22*H22,"") -> 171737500 | M22: 0.5 | N22: =IFERROR(IF(B22<>"Open","—",IF((G22*H22+Q22)<=0,"LIQUIDATION",IF((G22*H22+Q22)/(G22*H22)<=M22,"WARNING","OK"))),"—") -> — | O22: 6835 | P22: =IFERROR((IF(AND(B22="Closed",AD22<>""),AD22,O22))*H22,"") -> 170875000 | Q22: =IFERROR(IF(E22="Long",(IF(AND(B22="Closed",AD22<>""),AD22,O22)-G22)*H22*I22,(G22-IF(AND(B22="Closed",AD22<>""),AD22,O22))*H22*I22),"") -> 8625000 | R22: =IFERROR(Q22/(G22*H22),"") -> 0.050221996 | S22: =IFERROR(L22/(IFERROR(LOOKUP(2,1/('Transaction Log'!H5:H106<>""),'Transaction Log'!H5:H106),0)),"") -> 0.08377439 | T22: 46086 | U22: =IFERROR(IF(B22="Closed",T22-F22,TODAY()-F22),"") -> 0 | V22: 6969 | W22: 6835 | X22: =IFERROR(IF(OR(V22="",I22=""),"—",IF(E22="Long",(G22-V22)*H22*I22,(V22-G22)*H22*I22)),"—") -> 24875000 | Y22: =IFERROR(IF(OR(V22="",G22=""),"—",IF(E22="Long",(G22-V22)/G22,(V22-G22)/G22)),"—") -> 0.014484315 | Z22: =IFERROR(IF(OR(W22="",I22=""),"—",IF(E22="Long",(W22-G22)*H22*I22,(G22-W22)*H22*I22)),"—") -> 8625000 | AA22: =IFERROR(IF(OR(W22="",G22=""),"—",IF(E22="Long",(W22-G22)/G22,(G22-W22)/G22)),"—") -> 0.0050221996 | AB22: Market Opening Swing | AC22: =IFERROR(IF(E22="Long",(G22-V22)*H22*I22,(V22-G22)*H22*I22),"") -> 24875000 | AD22: =IFERROR(IF(OR(AF22="STOP LOSS HIT",AF22="TAKE PROFIT HIT"),AG22,""),"") -> 6835 | AE22: =IFERROR(IF(E22="Long",(IF(AND(B22="Closed",AD22<>""),AD22,O22)-G22)/G22,(G22-IF(AND(B22="Closed",AD22<>""),AD22,O22))/G22),"") -> 0.0050221996 | AF22: =IFERROR(IF(OR(V22="",W22=""),"No SL/TP",IF(E22="Long",IF(O22<=V22,"STOP LOSS HIT",IF(O22>=W22,"TAKE PROFIT HIT",IF(B22="Closed","CLOSED","Active"))),IF(O22>=V22,"STOP LOSS HIT",IF(O22<=W22,"TAKE PROFIT HIT",IF(B22="Closed","CLOSED","Active"))))),"—") -> TAKE PROFIT HIT | AG22: =IFERROR(IF(E22="Long",IF(O22<=V22,V22,IF(O22>=W22,W22,"")),IF(O22>=V22,V22,IF(O22<=W22,W22,""))),"") -> 6835 | AH22: =IFERROR(IF(B22<>"Open","—",IF(E22="Long",G22*(1-1/I22),G22*(1+1/I22))),"—") -> —
A23: =IFERROR(ROW()-5,"") -> 18 | B23: Closed | C23: Futures | D23: Oil | E23: Long | F23: 46086 | G23: 78.78 | H23: 750000 | I23: 20 | J23: =IFERROR(1/I23,"") -> 0.05 | K23: =IFERROR(G23*H23*I23,"") -> 1181700000 | L23: =IFERROR(G23*H23,"") -> 59085000 | M23: 0.5 | N23: =IFERROR(IF(B23<>"Open","—",IF((G23*H23+Q23)<=0,"LIQUIDATION",IF((G23*H23+Q23)/(G23*H23)<=M23,"WARNING","OK"))),"—") -> — | O23: 79.2 | P23: =IFERROR((IF(AND(B23="Closed",AD23<>""),AD23,O23))*H23,"") -> 59400000 | Q23: =IFERROR(IF(E23="Long",(IF(AND(B23="Closed",AD23<>""),AD23,O23)-G23)*H23*I23,(G23-IF(AND(B23="Closed",AD23<>""),AD23,O23))*H23*I23),"") -> 6300000 | R23: =IFERROR(Q23/(G23*H23),"") -> 0.10662605 | S23: =IFERROR(L23/(IFERROR(LOOKUP(2,1/('Transaction Log'!H5:H106<>""),'Transaction Log'!H5:H106),0)),"") -> 0.028821951 | T23: 46086 | U23: =IFERROR(IF(B23="Closed",T23-F23,TODAY()-F23),"") -> 0 | V23: 77.9 | W23: 79.2 | X23: =IFERROR(IF(OR(V23="",I23=""),"—",IF(E23="Long",(G23-V23)*H23*I23,(V23-G23)*H23*I23)),"—") -> 13200000 | Y23: =IFERROR(IF(OR(V23="",G23=""),"—",IF(E23="Long",(G23-V23)/G23,(V23-G23)/G23)),"—") -> 0.011170348 | Z23: =IFERROR(IF(OR(W23="",I23=""),"—",IF(E23="Long",(W23-G23)*H23*I23,(G23-W23)*H23*I23)),"—") -> 6300000 | AA23: =IFERROR(IF(OR(W23="",G23=""),"—",IF(E23="Long",(W23-G23)/G23,(G23-W23)/G23)),"—") -> 0.0053313024 | AB23: US Oil price jumps pullback swing | AC23: =IFERROR(IF(E23="Long",(G23-V23)*H23*I23,(V23-G23)*H23*I23),"") -> 13200000 | AD23: =IFERROR(IF(OR(AF23="STOP LOSS HIT",AF23="TAKE PROFIT HIT"),AG23,""),"") -> 79.2 | AE23: =IFERROR(IF(E23="Long",(IF(AND(B23="Closed",AD23<>""),AD23,O23)-G23)/G23,(G23-IF(AND(B23="Closed",AD23<>""),AD23,O23))/G23),"") -> 0.0053313024 | AF23: =IFERROR(IF(OR(V23="",W23=""),"No SL/TP",IF(E23="Long",IF(O23<=V23,"STOP LOSS HIT",IF(O23>=W23,"TAKE PROFIT HIT",IF(B23="Closed","CLOSED","Active"))),IF(O23>=V23,"STOP LOSS HIT",IF(O23<=W23,"TAKE PROFIT HIT",IF(B23="Closed","CLOSED","Active"))))),"—") -> TAKE PROFIT HIT | AG23: =IFERROR(IF(E23="Long",IF(O23<=V23,V23,IF(O23>=W23,W23,"")),IF(O23>=V23,V23,IF(O23<=W23,W23,""))),"") -> 79.2 | AH23: =IFERROR(IF(B23<>"Open","—",IF(E23="Long",G23*(1-1/I23),G23*(1+1/I23))),"—") -> —
A24: =IFERROR(ROW()-5,"") -> 19 | B24: Closed | C24: Forex | D24: USD/JPY | E24: Short | F24: 46085 | G24: 157 | H24: 800000 | I24: 20 | J24: =IFERROR(1/I24,"") -> 0.05 | K24: =IFERROR(G24*H24*I24,"") -> 2512000000 | L24: =IFERROR(G24*H24,"") -> 125600000 | M24: 0.5 | N24: =IFERROR(IF(B24<>"Open","—",IF((G24*H24+Q24)<=0,"LIQUIDATION",IF((G24*H24+Q24)/(G24*H24)<=M24,"WARNING","OK"))),"—") -> — | O24: 156.72 | P24: =IFERROR((IF(AND(B24="Closed",AD24<>""),AD24,O24))*H24,"") -> 125376000 | Q24: =IFERROR(IF(E24="Long",(IF(AND(B24="Closed",AD24<>""),AD24,O24)-G24)*H24*I24,(G24-IF(AND(B24="Closed",AD24<>""),AD24,O24))*H24*I24),"") -> 4480000 | R24: =IFERROR(Q24/(G24*H24),"") -> 0.03566879 | S24: =IFERROR(L24/(IFERROR(LOOKUP(2,1/('Transaction Log'!H5:H106<>""),'Transaction Log'!H5:H106),0)),"") -> 0.061268293 | T24: 46086 | U24: =IFERROR(IF(B24="Closed",T24-F24,TODAY()-F24),"") -> 1 | V24: 158.7 | W24: 156.72 | X24: =IFERROR(IF(OR(V24="",I24=""),"—",IF(E24="Long",(G24-V24)*H24*I24,(V24-G24)*H24*I24)),"—") -> 27200000 | Y24: =IFERROR(IF(OR(V24="",G24=""),"—",IF(E24="Long",(G24-V24)/G24,(V24-G24)/G24)),"—") -> 0.010828025 | Z24: =IFERROR(IF(OR(W24="",I24=""),"—",IF(E24="Long",(W24-G24)*H24*I24,(G24-W24)*H24*I24)),"—") -> 4480000 | AA24: =IFERROR(IF(OR(W24="",G24=""),"—",IF(E24="Long",(W24-G24)/G24,(G24-W24)/G24)),"—") -> 0.0017834395 | AB24: USD depreciation for tension, Market sentiment bearish | AC24: =IFERROR(IF(E24="Long",(G24-V24)*H24*I24,(V24-G24)*H24*I24),"") -> 27200000 | AD24: =IFERROR(IF(OR(AF24="STOP LOSS HIT",AF24="TAKE PROFIT HIT"),AG24,""),"") -> 156.72 | AE24: =IFERROR(IF(E24="Long",(IF(AND(B24="Closed",AD24<>""),AD24,O24)-G24)/G24,(G24-IF(AND(B24="Closed",AD24<>""),AD24,O24))/G24),"") -> 0.0017834395 | AF24: =IFERROR(IF(OR(V24="",W24=""),"No SL/TP",IF(E24="Long",IF(O24<=V24,"STOP LOSS HIT",IF(O24>=W24,"TAKE PROFIT HIT",IF(B24="Closed","CLOSED","Active"))),IF(O24>=V24,"STOP LOSS HIT",IF(O24<=W24,"TAKE PROFIT HIT",IF(B24="Closed","CLOSED","Active"))))),"—") -> TAKE PROFIT HIT | AG24: =IFERROR(IF(E24="Long",IF(O24<=V24,V24,IF(O24>=W24,W24,"")),IF(O24>=V24,V24,IF(O24<=W24,W24,""))),"") -> 156.72 | AH24: =IFERROR(IF(B24<>"Open","—",IF(E24="Long",G24*(1-1/I24),G24*(1+1/I24))),"—") -> —
A25: =IFERROR(ROW()-5,"") -> 20 | B25: Closed | C25: Crypto | D25: BTC | E25: Short | F25: 46085 | G25: 73988 | H25: 1000 | I25: 5 | J25: =IFERROR(1/I25,"") -> 0.2 | K25: =IFERROR(G25*H25*I25,"") -> 369940000 | L25: =IFERROR(G25*H25,"") -> 73988000 | M25: 0.5 | N25: =IFERROR(IF(B25<>"Open","—",IF((G25*H25+Q25)<=0,"LIQUIDATION",IF((G25*H25+Q25)/(G25*H25)<=M25,"WARNING","OK"))),"—") -> — | O25: 73370.54 | P25: =IFERROR((IF(AND(B25="Closed",AD25<>""),AD25,O25))*H25,"") -> 73370540 | Q25: =IFERROR(IF(E25="Long",(IF(AND(B25="Closed",AD25<>""),AD25,O25)-G25)*H25*I25,(G25-IF(AND(B25="Closed",AD25<>""),AD25,O25))*H25*I25),"") -> 3087300 | R25: =IFERROR(Q25/(G25*H25),"") -> 0.041727037 | S25: =IFERROR(L25/(IFERROR(LOOKUP(2,1/('Transaction Log'!H5:H106<>""),'Transaction Log'!H5:H106),0)),"") -> 0.036091707 | T25: 46085 | U25: =IFERROR(IF(B25="Closed",T25-F25,TODAY()-F25),"") -> 0 | V25: 74250 | W25: 72560 | X25: =IFERROR(IF(OR(V25="",I25=""),"—",IF(E25="Long",(G25-V25)*H25*I25,(V25-G25)*H25*I25)),"—") -> 1310000 | Y25: =IFERROR(IF(OR(V25="",G25=""),"—",IF(E25="Long",(G25-V25)/G25,(V25-G25)/G25)),"—") -> 0.0035411148 | Z25: =IFERROR(IF(OR(W25="",I25=""),"—",IF(E25="Long",(W25-G25)*H25*I25,(G25-W25)*H25*I25)),"—") -> 7140000 | AA25: =IFERROR(IF(OR(W25="",G25=""),"—",IF(E25="Long",(W25-G25)/G25,(G25-W25)/G25)),"—") -> 0.019300427 | AB25: Geopolitical tensions short-term | AC25: =IFERROR(IF(E25="Long",(G25-V25)*H25*I25,(V25-G25)*H25*I25),"") -> 1310000 | AD25: =IFERROR(IF(OR(AF25="STOP LOSS HIT",AF25="TAKE PROFIT HIT"),AG25,""),"") | AE25: =IFERROR(IF(E25="Long",(IF(AND(B25="Closed",AD25<>""),AD25,O25)-G25)/G25,(G25-IF(AND(B25="Closed",AD25<>""),AD25,O25))/G25),"") -> 0.0083454074 | AF25: =IFERROR(IF(OR(V25="",W25=""),"No SL/TP",IF(E25="Long",IF(O25<=V25,"STOP LOSS HIT",IF(O25>=W25,"TAKE PROFIT HIT",IF(B25="Closed","CLOSED","Active"))),IF(O25>=V25,"STOP LOSS HIT",IF(O25<=W25,"TAKE PROFIT HIT",IF(B25="Closed","CLOSED","Active"))))),"—") -> CLOSED | AG25: =IFERROR(IF(E25="Long",IF(O25<=V25,V25,IF(O25>=W25,W25,"")),IF(O25>=V25,V25,IF(O25<=W25,W25,""))),"") | AH25: =IFERROR(IF(B25<>"Open","—",IF(E25="Long",G25*(1-1/I25),G25*(1+1/I25))),"—") -> —
A26: =IFERROR(ROW()-5,"") -> 21 | B26: Closed | C26: Stock | D26: RHMD | E26: Short | F26: 46085 | G26: 1599.5 | H26: 5000 | I26: 10 | J26: =IFERROR(1/I26,"") -> 0.1 | K26: =IFERROR(G26*H26*I26,"") -> 79975000 | L26: =IFERROR(G26*H26,"") -> 7997500 | M26: 0.5 | N26: =IFERROR(IF(B26<>"Open","—",IF((G26*H26+Q26)<=0,"LIQUIDATION",IF((G26*H26+Q26)/(G26*H26)<=M26,"WARNING","OK"))),"—") -> — | O26: 1570 | P26: =IFERROR((IF(AND(B26="Closed",AD26<>""),AD26,O26))*H26,"") -> 7850000 | Q26: =IFERROR(IF(E26="Long",(IF(AND(B26="Closed",AD26<>""),AD26,O26)-G26)*H26*I26,(G26-IF(AND(B26="Closed",AD26<>""),AD26,O26))*H26*I26),"") -> 1475000 | R26: =IFERROR(Q26/(G26*H26),"") -> 0.18443264 | S26: =IFERROR(L26/(IFERROR(LOOKUP(2,1/('Transaction Log'!H5:H106<>""),'Transaction Log'!H5:H106),0)),"") -> 0.0039012195 | T26: 46086 | U26: =IFERROR(IF(B26="Closed",T26-F26,TODAY()-F26),"") -> 1 | V26: 1620 | W26: 1570 | X26: =IFERROR(IF(OR(V26="",I26=""),"—",IF(E26="Long",(G26-V26)*H26*I26,(V26-G26)*H26*I26)),"—") -> 1025000 | Y26: =IFERROR(IF(OR(V26="",G26=""),"—",IF(E26="Long",(G26-V26)/G26,(V26-G26)/G26)),"—") -> 0.012816505 | Z26: =IFERROR(IF(OR(W26="",I26=""),"—",IF(E26="Long",(W26-G26)*H26*I26,(G26-W26)*H26*I26)),"—") -> 1475000 | AA26: =IFERROR(IF(OR(W26="",G26=""),"—",IF(E26="Long",(W26-G26)/G26,(G26-W26)/G26)),"—") -> 0.018443264 | AB26: European defense budget increase but looks bearish | AC26: =IFERROR(IF(E26="Long",(G26-V26)*H26*I26,(V26-G26)*H26*I26),"") -> 1025000 | AD26: =IFERROR(IF(OR(AF26="STOP LOSS HIT",AF26="TAKE PROFIT HIT"),AG26,""),"") -> 1570 | AE26: =IFERROR(IF(E26="Long",(IF(AND(B26="Closed",AD26<>""),AD26,O26)-G26)/G26,(G26-IF(AND(B26="Closed",AD26<>""),AD26,O26))/G26),"") -> 0.018443264 | AF26: =IFERROR(IF(OR(V26="",W26=""),"No SL/TP",IF(E26="Long",IF(O26<=V26,"STOP LOSS HIT",IF(O26>=W26,"TAKE PROFIT HIT",IF(B26="Closed","CLOSED","Active"))),IF(O26>=V26,"STOP LOSS HIT",IF(O26<=W26,"TAKE PROFIT HIT",IF(B26="Closed","CLOSED","Active"))))),"—") -> TAKE PROFIT HIT | AG26: =IFERROR(IF(E26="Long",IF(O26<=V26,V26,IF(O26>=W26,W26,"")),IF(O26>=V26,V26,IF(O26<=W26,W26,""))),"") -> 1570 | AH26: =IFERROR(IF(B26<>"Open","—",IF(E26="Long",G26*(1-1/I26),G26*(1+1/I26))),"—") -> —
A27: =IFERROR(ROW()-5,"") -> 22 | B27: Closed | C27: ETF | D27: REMX | E27: Long | F27: 46085 | G27: 20.69 | H27: 800000 | I27: 25 | J27: =IFERROR(1/I27,"") -> 0.04 | K27: =IFERROR(G27*H27*I27,"") -> 4.138e+08 | L27: =IFERROR(G27*H27,"") -> 16552000 | M27: 0.5 | N27: =IFERROR(IF(B27<>"Open","—",IF((G27*H27+Q27)<=0,"LIQUIDATION",IF((G27*H27+Q27)/(G27*H27)<=M27,"WARNING","OK"))),"—") -> — | O27: 20.47 | P27: =IFERROR((IF(AND(B27="Closed",AD27<>""),AD27,O27))*H27,"") -> 16376000 | Q27: =IFERROR(IF(E27="Long",(IF(AND(B27="Closed",AD27<>""),AD27,O27)-G27)*H27*I27,(G27-IF(AND(B27="Closed",AD27<>""),AD27,O27))*H27*I27),"") -> -4400000 | R27: =IFERROR(Q27/(G27*H27),"") -> -0.2658289 | S27: =IFERROR(L27/(IFERROR(LOOKUP(2,1/('Transaction Log'!H5:H106<>""),'Transaction Log'!H5:H106),0)),"") -> 0.0080741463 | T27: 46086 | U27: =IFERROR(IF(B27="Closed",T27-F27,TODAY()-F27),"") -> 1 | V27: 20.47 | W27: 21.3 | X27: =IFERROR(IF(OR(V27="",I27=""),"—",IF(E27="Long",(G27-V27)*H27*I27,(V27-G27)*H27*I27)),"—") -> 4400000 | Y27: =IFERROR(IF(OR(V27="",G27=""),"—",IF(E27="Long",(G27-V27)/G27,(V27-G27)/G27)),"—") -> 0.010633156 | Z27: =IFERROR(IF(OR(W27="",I27=""),"—",IF(E27="Long",(W27-G27)*H27*I27,(G27-W27)*H27*I27)),"—") -> 12200000 | AA27: =IFERROR(IF(OR(W27="",G27=""),"—",IF(E27="Long",(W27-G27)/G27,(G27-W27)/G27)),"—") -> 0.029482842 | AB27: Rare minerals demand increase + tech ind. need | AC27: =IFERROR(IF(E27="Long",(G27-V27)*H27*I27,(V27-G27)*H27*I27),"") -> 4400000 | AD27: =IFERROR(IF(OR(AF27="STOP LOSS HIT",AF27="TAKE PROFIT HIT"),AG27,""),"") -> 20.47 | AE27: =IFERROR(IF(E27="Long",(IF(AND(B27="Closed",AD27<>""),AD27,O27)-G27)/G27,(G27-IF(AND(B27="Closed",AD27<>""),AD27,O27))/G27),"") -> -0.010633156 | AF27: =IFERROR(IF(OR(V27="",W27=""),"No SL/TP",IF(E27="Long",IF(O27<=V27,"STOP LOSS HIT",IF(O27>=W27,"TAKE PROFIT HIT",IF(B27="Closed","CLOSED","Active"))),IF(O27>=V27,"STOP LOSS HIT",IF(O27<=W27,"TAKE PROFIT HIT",IF(B27="Closed","CLOSED","Active"))))),"—") -> STOP LOSS HIT | AG27: =IFERROR(IF(E27="Long",IF(O27<=V27,V27,IF(O27>=W27,W27,"")),IF(O27>=V27,V27,IF(O27<=W27,W27,""))),"") -> 20.47 | AH27: =IFERROR(IF(B27<>"Open","—",IF(E27="Long",G27*(1-1/I27),G27*(1+1/I27))),"—") -> —
A28: =IFERROR(ROW()-5,"") -> 23 | B28: Closed | C28: Futures | D28: Oil | E28: Long | F28: 46082 | G28: 70.9 | H28: 100000 | I28: 10 | J28: =IFERROR(1/I28,"") -> 0.1 | K28: =IFERROR(G28*H28*I28,"") -> 70900000 | L28: =IFERROR(G28*H28,"") -> 7090000 | M28: 0.5 | N28: =IFERROR(IF(B28<>"Open","—",IF((G28*H28+Q28)<=0,"LIQUIDATION",IF((G28*H28+Q28)/(G28*H28)<=M28,"WARNING","OK"))),"—") -> — | O28: 76 | P28: =IFERROR((IF(AND(B28="Closed",AD28<>""),AD28,O28))*H28,"") -> 7600000 | Q28: =IFERROR(IF(E28="Long",(IF(AND(B28="Closed",AD28<>""),AD28,O28)-G28)*H28*I28,(G28-IF(AND(B28="Closed",AD28<>""),AD28,O28))*H28*I28),"") -> 5100000 | R28: =IFERROR(Q28/(G28*H28),"") -> 0.71932299 | S28: =IFERROR(L28/(IFERROR(LOOKUP(2,1/('Transaction Log'!H5:H106<>""),'Transaction Log'!H5:H106),0)),"") -> 0.0034585366 | T28: 46085 | U28: =IFERROR(IF(B28="Closed",T28-F28,TODAY()-F28),"") -> 3 | V28: 68.5 | W28: 76 | X28: =IFERROR(IF(OR(V28="",I28=""),"—",IF(E28="Long",(G28-V28)*H28*I28,(V28-G28)*H28*I28)),"—") -> 2400000 | Y28: =IFERROR(IF(OR(V28="",G28=""),"—",IF(E28="Long",(G28-V28)/G28,(V28-G28)/G28)),"—") -> 0.033850494 | Z28: =IFERROR(IF(OR(W28="",I28=""),"—",IF(E28="Long",(W28-G28)*H28*I28,(G28-W28)*H28*I28)),"—") -> 5100000 | AA28: =IFERROR(IF(OR(W28="",G28=""),"—",IF(E28="Long",(W28-G28)/G28,(G28-W28)/G28)),"—") -> 0.071932299 | AB28: US-Iran Tensions | AC28: =IFERROR(IF(E28="Long",(G28-V28)*H28*I28,(V28-G28)*H28*I28),"") -> 2400000 | AD28: =IFERROR(IF(OR(AF28="STOP LOSS HIT",AF28="TAKE PROFIT HIT"),AG28,""),"") -> 76 | AE28: =IFERROR(IF(E28="Long",(IF(AND(B28="Closed",AD28<>""),AD28,O28)-G28)/G28,(G28-IF(AND(B28="Closed",AD28<>""),AD28,O28))/G28),"") -> 0.071932299 | AF28: =IFERROR(IF(OR(V28="",W28=""),"No SL/TP",IF(E28="Long",IF(O28<=V28,"STOP LOSS HIT",IF(O28>=W28,"TAKE PROFIT HIT",IF(B28="Closed","CLOSED","Active"))),IF(O28>=V28,"STOP LOSS HIT",IF(O28<=W28,"TAKE PROFIT HIT",IF(B28="Closed","CLOSED","Active"))))),"—") -> TAKE PROFIT HIT | AG28: =IFERROR(IF(E28="Long",IF(O28<=V28,V28,IF(O28>=W28,W28,"")),IF(O28>=V28,V28,IF(O28<=W28,W28,""))),"") -> 76 | AH28: =IFERROR(IF(B28<>"Open","—",IF(E28="Long",G28*(1-1/I28),G28*(1+1/I28))),"—") -> —
A29: =IFERROR(ROW()-5,"") -> 24 | B29: Open | C29: Futures | D29: Oil | E29: Long | F29: 46095 | G29: 97.633 | H29: 1200000 | I29: 20 | J29: =IFERROR(1/I29,"") -> 0.05 | K29: =IFERROR(G29*H29*I29,"") -> 2343192000 | L29: =IFERROR(G29*H29,"") -> 117159600 | M29: 0.5 | N29: =IFERROR(IF(B29<>"Open","—",IF((G29*H29+Q29)<=0,"LIQUIDATION",IF((G29*H29+Q29)/(G29*H29)<=M29,"WARNING","OK"))),"—") -> OK | O29: 98.71 | P29: =IFERROR((IF(AND(B29="Closed",AD29<>""),AD29,O29))*H29,"") -> 1.18452e+08 | Q29: =IFERROR(IF(E29="Long",(IF(AND(B29="Closed",AD29<>""),AD29,O29)-G29)*H29*I29,(G29-IF(AND(B29="Closed",AD29<>""),AD29,O29))*H29*I29),"") -> 25848000 | R29: =IFERROR(Q29/(G29*H29),"") -> 0.22062213 | S29: =IFERROR(L29/(IFERROR(LOOKUP(2,1/('Transaction Log'!H5:H106<>""),'Transaction Log'!H5:H106),0)),"") -> 0.057151024 | U29: =IFERROR(IF(B29="Closed",T29-F29,TODAY()-F29),"") -> 1 | V29: 92 | W29: 148.5 | X29: =IFERROR(IF(OR(V29="",I29=""),"—",IF(E29="Long",(G29-V29)*H29*I29,(V29-G29)*H29*I29)),"—") -> 1.35192e+08 | Y29: =IFERROR(IF(OR(V29="",G29=""),"—",IF(E29="Long",(G29-V29)/G29,(V29-G29)/G29)),"—") -> 0.057695656 | Z29: =IFERROR(IF(OR(W29="",I29=""),"—",IF(E29="Long",(W29-G29)*H29*I29,(G29-W29)*H29*I29)),"—") -> 1.220808e+09 | AA29: =IFERROR(IF(OR(W29="",G29=""),"—",IF(E29="Long",(W29-G29)/G29,(G29-W29)/G29)),"—") -> 0.52100212 | AB29: LONG oil war | AC29: =IFERROR(IF(E29="Long",(G29-V29)*H29*I29,(V29-G29)*H29*I29),"") -> 1.35192e+08 | AD29: =IFERROR(IF(OR(AF29="STOP LOSS HIT",AF29="TAKE PROFIT HIT"),AG29,""),"") | AE29: =IFERROR(IF(E29="Long",(IF(AND(B29="Closed",AD29<>""),AD29,O29)-G29)/G29,(G29-IF(AND(B29="Closed",AD29<>""),AD29,O29))/G29),"") -> 0.011031106 | AF29: =IFERROR(IF(OR(V29="",W29=""),"No SL/TP",IF(E29="Long",IF(O29<=V29,"STOP LOSS HIT",IF(O29>=W29,"TAKE PROFIT HIT",IF(B29="Closed","CLOSED","Active"))),IF(O29>=V29,"STOP LOSS HIT",IF(O29<=W29,"TAKE PROFIT HIT",IF(B29="Closed","CLOSED","Active"))))),"—") -> Active | AG29: =IFERROR(IF(E29="Long",IF(O29<=V29,V29,IF(O29>=W29,W29,"")),IF(O29>=V29,V29,IF(O29<=W29,W29,""))),"") | AH29: =IFERROR(IF(B29<>"Open","—",IF(E29="Long",G29*(1-1/I29),G29*(1+1/I29))),"—") -> 92.75135
A30: =IFERROR(ROW()-5,"") -> 25 | B30: Open | C30: Futures | D30: Oil | E30: Long | F30: 46095 | G30: 97.633 | H30: 800000 | I30: 20 | J30: =IFERROR(1/I30,"") -> 0.05 | K30: =IFERROR(G30*H30*I30,"") -> 1562128000 | L30: =IFERROR(G30*H30,"") -> 78106400 | M30: 0.5 | N30: =IFERROR(IF(B30<>"Open","—",IF((G30*H30+Q30)<=0,"LIQUIDATION",IF((G30*H30+Q30)/(G30*H30)<=M30,"WARNING","OK"))),"—") -> OK | O30: 98.71 | P30: =IFERROR((IF(AND(B30="Closed",AD30<>""),AD30,O30))*H30,"") -> 78968000 | Q30: =IFERROR(IF(E30="Long",(IF(AND(B30="Closed",AD30<>""),AD30,O30)-G30)*H30*I30,(G30-IF(AND(B30="Closed",AD30<>""),AD30,O30))*H30*I30),"") -> 17232000 | R30: =IFERROR(Q30/(G30*H30),"") -> 0.22062213 | S30: =IFERROR(L30/(IFERROR(LOOKUP(2,1/('Transaction Log'!H5:H106<>""),'Transaction Log'!H5:H106),0)),"") -> 0.038100683 | U30: =IFERROR(IF(B30="Closed",T30-F30,TODAY()-F30),"") -> 1 | V30: 92 | W30: 138 | X30: =IFERROR(IF(OR(V30="",I30=""),"—",IF(E30="Long",(G30-V30)*H30*I30,(V30-G30)*H30*I30)),"—") -> 90128000 | Y30: =IFERROR(IF(OR(V30="",G30=""),"—",IF(E30="Long",(G30-V30)/G30,(V30-G30)/G30)),"—") -> 0.057695656 | Z30: =IFERROR(IF(OR(W30="",I30=""),"—",IF(E30="Long",(W30-G30)*H30*I30,(G30-W30)*H30*I30)),"—") -> 6.45872e+08 | AA30: =IFERROR(IF(OR(W30="",G30=""),"—",IF(E30="Long",(W30-G30)/G30,(G30-W30)/G30)),"—") -> 0.41345652 | AB30: LONG Oil war Mult positions | AC30: =IFERROR(IF(E30="Long",(G30-V30)*H30*I30,(V30-G30)*H30*I30),"") -> 90128000 | AD30: =IFERROR(IF(OR(AF30="STOP LOSS HIT",AF30="TAKE PROFIT HIT"),AG30,""),"") | AE30: =IFERROR(IF(E30="Long",(IF(AND(B30="Closed",AD30<>""),AD30,O30)-G30)/G30,(G30-IF(AND(B30="Closed",AD30<>""),AD30,O30))/G30),"") -> 0.011031106 | AF30: =IFERROR(IF(OR(V30="",W30=""),"No SL/TP",IF(E30="Long",IF(O30<=V30,"STOP LOSS HIT",IF(O30>=W30,"TAKE PROFIT HIT",IF(B30="Closed","CLOSED","Active"))),IF(O30>=V30,"STOP LOSS HIT",IF(O30<=W30,"TAKE PROFIT HIT",IF(B30="Closed","CLOSED","Active"))))),"—") -> Active | AG30: =IFERROR(IF(E30="Long",IF(O30<=V30,V30,IF(O30>=W30,W30,"")),IF(O30>=V30,V30,IF(O30<=W30,W30,""))),"") | AH30: =IFERROR(IF(B30<>"Open","—",IF(E30="Long",G30*(1-1/I30),G30*(1+1/I30))),"—") -> 92.75135

Sheet Investor Withdrawals
A1: INVESTOR WITHDRAWALS // LIVE PRO-RATA TRACKER
A2: Net Balance and Fund % auto-recalculate for all players on every deposit or withdrawal.
A3: Blue=input | White=formula | Green=cross-sheet | Partial: enter amt in col O, P&L scales to fraction
A5: # | B5: Player Name | C5: First Deposit Date | D5: Lockup (days) | E5: Unlock Date | F5: Days to Unlock | G5: Lockup Status | H5: Total Deposited ($) | I5: Total Paid Out ($) | J5: Net Balance in Fund ($) | K5: Fund % (live) | L5: Fund P&L ($) | M5: Full P&L Share ($) | N5: Withdrawal Date | O5: Withdrawal Amt ($) | P5: % of Stake Withdrawn | Q5: P&L on Withdrawal ($) | R5: Net Payout ($) | S5: Remaining Balance ($) | T5: New Fund % | U5: Status | V5: Notes
A6: 1 | B6: Kimmo | C6: 46082 | D6: 0 | E6: =IFERROR(C6+D6,"") -> 46082 | F6: =IFERROR(E6-TODAY(),"") -> -14 | G6: =IFERROR(IF(TODAY()>=E6,"UNLOCKED","LOCKED"),"") -> UNLOCKED | H6: =IFERROR(SUMIF('Transaction Log'!C5:C106,B6,'Transaction Log'!E5:E106),0) -> 2000000000 | I6: =IFERROR(SUMIF('Transaction Log'!C5:C106,B6,'Transaction Log'!F5:F106),0) -> 0 | J6: =IFERROR(H6-I6,0) -> 2000000000 | K6: =IFERROR(J6/(IFERROR(LOOKUP(2,1/('Transaction Log'!H5:H106<>""),'Transaction Log'!H5:H106),0)),0) -> 0.97560976 | L6: =IFERROR(SUM(Positions!Q6:Q105),0) -> 1.1832186e+09 | M6: =IFERROR(K6*L6,0) -> 1.1543596e+09 | P6: =IFERROR(O6/J6,0) -> 0 | Q6: =IFERROR(P6*M6,0) -> 0 | R6: =IFERROR(IF(O6>0,O6+Q6,""),"") | S6: =IFERROR(J6-O6,J6) -> 2000000000 | T6: =IFERROR(S6/(IFERROR(LOOKUP(2,1/('Transaction Log'!H5:H106<>""),'Transaction Log'!H5:H106),0)),0) -> 0.97560976 | U6: =IFERROR(IF(J6<=0,"No Balance",IF(O6<=0,"No Withdrawal",IF(TODAY()<E6,"LOCKED",IF(O6>J6,"Exceeds Balance","Approved")))),"—") -> No Withdrawal
